Workbook
Name Product: 'Product List'!$A:$A
Name Products: #REF!
Name Family: 'Product Families'!$A:$A
Name Names: Personnel!$A$10:$A$32
Name ManualSheet1: 'Production Sheet - Manual'!$A$1:$I$77
Name ManualSheet2: 'Production Sheet - Manual'!$J$1:$AK$97

Sheet Wholesale Pricing
H1: Part 1 | I1: Part 2 | J1: Part 3 | K1: Part 4 | L1: Part 5 | M1: Part 1 Calcs | R1: Part 2 Calcs | W1: Part 3 Calcs | AB1: Part 4 Calcs | AG1: Part 5 Calcs
A2: Family Code | B2: Wholesale Price | C2: Pack Quantity | D2: Single Item Price | E2: Total from Target Amount | G2: Notes | H2: Code | I2: Code | J2: Code | K2: Code | L2: Code | M2: Target Rate | N2: Amount | O2: Single Amount | P2: % | Q2: Wholesale Calc | R2: Target Rate | S2: Amount | T2: Single Amount | U2: % | V2: Wholesale Calc | W2: Target Rate | X2: Amount | Y2: Single Amount | Z2: % | AA2: Wholesale Calc | AB2: Target Rate | AC2: Amount | AD2: Single Amount | AE2: % | AF2: Wholesale Calc | AG2: Target Rate | AH2: Amount | AI2: Single Amount | AJ2: % | AK2: Wholesale Calc
A3: ABB1 | B3: 2.64 | C3: 8 | D3: =iferror(B3/C3,"") -> 0.33 | E3: =sum(O3+T3+Y3+AD3+AI3) -> 0.08625 | H3: ABB1 | I3: ABBP | M3: {=iferror(xlookup($H3,'Product Families'!$A:$A,'Product Families'!$P:$P),"")} -> 0.05 | N3: {=iferror(xlookup($H3,'Product Families'!$A:$A,'Product Families'!$Q:$Q),"")} -> 1 | O3: =iferror(M3/N3,"") -> 0.05 | P3: =iferror(O3/$E3,"") -> 0.57971014 | Q3: =round($D3*P3,2) -> 0.19 | R3: {=iferror(xlookup($I3,'Product Families'!$A:$A,'Product Families'!$P:$P),"")} -> 0.29 | S3: {=iferror(xlookup($I3,'Product Families'!$A:$A,'Product Families'!$Q:$Q),"")} -> 8 | T3: =iferror(R3/S3,"") -> 0.03625 | U3: =iferror(T3/$E3,"") -> 0.42028986 | V3: =round($D3*U3,2) -> 0.14 | W3: {=iferror(xlookup($J3,'Product Families'!$A:$A,'Product Families'!$P:$P),"")} | X3: {=iferror(xlookup($J3,'Product Families'!$A:$A,'Product Families'!$Q:$Q),"")} | Y3: =iferror(W3/X3,"") | Z3: =iferror(Y3/$E3,"") -> 0 | AA3: =round($D3*Z3,2) -> 0 | AB3: {=iferror(xlookup($K3,'Product Families'!$A:$A,'Product Families'!$P:$P),"")} | AC3: {=iferror(xlookup($K3,'Product Families'!$A:$A,'Product Families'!$Q:$Q),"")} | AD3: =iferror(AB3/AC3,"") | AE3: =iferror(AD3/$E3,"") -> 0 | AF3: =round($D3*AE3,2) -> 0 | AG3: {=iferror(xlookup($L3,'Product Families'!$A:$A,'Product Families'!$P:$P),"")} | AH3: {=iferror(xlookup($L3,'Product Families'!$A:$A,'Product Families'!$Q:$Q),"")} | AI3: =iferror(AG3/AH3,"") | AJ3: =iferror(AI3/$E3,"") -> 0 | AK3: =round($D3*AJ3,2) -> 0
A4: ABP | B4: 15.17 | C4: 1 | D4: =iferror(B4/C4,"") -> 15.17 | E4: =sum(O4+T4+Y4+AD4+AI4) -> 0 | H4: ABP | M4: {=iferror(xlookup($H4,'Product Families'!$A:$A,'Product Families'!$P:$P),"")} -> 0.19 | N4: {=iferror(xlookup($H4,'Product Families'!$A:$A,'Product Families'!$Q:$Q),"")} | O4: =iferror(M4/N4,"") | P4: =iferror(O4/$E4,"") | Q4: =round($D4*P4,2) -> 0 | R4: {=iferror(xlookup($I4,'Product Families'!$A:$A,'Product Families'!$P:$P),"")} | S4: {=iferror(xlookup($I4,'Product Families'!$A:$A,'Product Families'!$Q:$Q),"")} | T4: =iferror(R4/S4,"") | U4: =iferror(T4/$E4,"") | V4: =round($D4*U4,2) -> 0 | W4: {=iferror(xlookup($J4,'Product Families'!$A:$A,'Product Families'!$P:$P),"")} | X4: {=iferror(xlookup($J4,'Product Families'!$A:$A,'Product Families'!$Q:$Q),"")} | Y4: =iferror(W4/X4,"") | Z4: =iferror(Y4/$E4,"") | AA4: =round($D4*Z4,2) -> 0 | AB4: {=iferror(xlookup($K4,'Product Families'!$A:$A,'Product Families'!$P:$P),"")} | AC4: {=iferror(xlookup($K4,'Product Families'!$A:$A,'Product Families'!$Q:$Q),"")} | AD4: =iferror(AB4/AC4,"") | AE4: =iferror(AD4/$E4,"") | AF4: =round($D4*AE4,2) -> 0 | AG4: {=iferror(xlookup($L4,'Product Families'!$A:$A,'Product Families'!$P:$P),"")} | AH4: {=iferror(xlookup($L4,'Product Families'!$A:$A,'Product Families'!$Q:$Q),"")} | AI4: =iferror(AG4/AH4,"") | AJ4: =iferror(AI4/$E4,"") | AK4: =round($D4*AJ4,2) -> 0
A5: ABPC | B5: 10.96 | C5: 5 | D5: =iferror(B5/C5,"") -> 2.192 | E5: =sum(O5+T5+Y5+AD5+AI5) -> 0 | H5: ABPC | M5: {=iferror(xlookup($H5,'Product Families'!$A:$A,'Product Families'!$P:$P),"")} -> 0.25 | N5: {=iferror(xlookup($H5,'Product Families'!$A:$A,'Product Families'!$Q:$Q),"")} | O5: =iferror(M5/N5,"") | P5: =iferror(O5/$E5,"") | Q5: =round($D5*P5,2) -> 0 | R5: {=iferror(xlookup($I5,'Product Families'!$A:$A,'Product Families'!$P:$P),"")} | S5: {=iferror(xlookup($I5,'Product Families'!$A:$A,'Product Families'!$Q:$Q),"")} | T5: =iferror(R5/S5,"") | U5: =iferror(T5/$E5,"") | V5: =round($D5*U5,2) -> 0 | W5: {=iferror(xlookup($J5,'Product Families'!$A:$A,'Product Families'!$P:$P),"")} | X5: {=iferror(xlookup($J5,'Product Families'!$A:$A,'Product Families'!$Q:$Q),"")} | Y5: =iferror(W5/X5,"") | Z5: =iferror(Y5/$E5,"") | AA5: =round($D5*Z5,2) -> 0 | AB5: {=iferror(xlookup($K5,'Product Families'!$A:$A,'Product Families'!$P:$P),"")} | AC5: {=iferror(xlookup($K5,'Product Families'!$A:$A,'Product Families'!$Q:$Q),"")} | AD5: =iferror(AB5/AC5,"") | AE5: =iferror(AD5/$E5,"") | AF5: =round($D5*AE5,2) -> 0 | AG5: {=iferror(xlookup($L5,'Product Families'!$A:$A,'Product Families'!$P:$P),"")} | AH5: {=iferror(xlookup($L5,'Product Families'!$A:$A,'Product Families'!$Q:$Q),"")} | AI5: =iferror(AG5/AH5,"") | AJ5: =iferror(AI5/$E5,"") | AK5: =round($D5*AJ5,2) -> 0
A6: ABPCULB | B6: 9.81 | C6: 5 | D6: =iferror(B6/C6,"") -> 1.962 | E6: =sum(O6+T6+Y6+AD6+AI6) -> 0 | H6: ABPCULB | M6: {=iferror(xlookup($H6,'Product Families'!$A:$A,'Product Families'!$P:$P),"")} -> 0.94 | N6: {=iferror(xlookup($H6,'Product Families'!$A:$A,'Product Families'!$Q:$Q),"")} | O6: =iferror(M6/N6,"") | P6: =iferror(O6/$E6,"") | Q6: =round($D6*P6,2) -> 0 | R6: {=iferror(xlookup($I6,'Product Families'!$A:$A,'Product Families'!$P:$P),"")} | S6: {=iferror(xlookup($I6,'Product Families'!$A:$A,'Product Families'!$Q:$Q),"")} | T6: =iferror(R6/S6,"") | U6: =iferror(T6/$E6,"") | V6: =round($D6*U6,2) -> 0 | W6: {=iferror(xlookup($J6,'Product Families'!$A:$A,'Product Families'!$P:$P),"")} | X6: {=iferror(xlookup($J6,'Product Families'!$A:$A,'Product Families'!$Q:$Q),"")} | Y6: =iferror(W6/X6,"") | Z6: =iferror(Y6/$E6,"") | AA6: =round($D6*Z6,2) -> 0 | AB6: {=iferror(xlookup($K6,'Product Families'!$A:$A,'Product Families'!$P:$P),"")} | AC6: {=iferror(xlookup($K6,'Product Families'!$A:$A,'Product Families'!$Q:$Q),"")} | AD6: =iferror(AB6/AC6,"") | AE6: =iferror(AD6/$E6,"") | AF6: =round($D6*AE6,2) -> 0 | AG6: {=iferror(xlookup($L6,'Product Families'!$A:$A,'Product Families'!$P:$P),"")} | AH6: {=iferror(xlookup($L6,'Product Families'!$A:$A,'Product Families'!$Q:$Q),"")} | AI6: =iferror(AG6/AH6,"") | AJ6: =iferror(AI6/$E6,"") | AK6: =round($D6*AJ6,2) -> 0
A7: ACBB | B7: 13.3 | C7: 6 | D7: =iferror(B7/C7,"") -> 2.2166667 | E7: =sum(O7+T7+Y7+AD7+AI7) -> 0 | H7: ACBB | I7: ACBBL | J7: ACBBP | M7: {=iferror(xlookup($H7,'Product Families'!$A:$A,'Product Families'!$P:$P),"")} -> 0.1 | N7: {=iferror(xlookup($H7,'Product Families'!$A:$A,'Product Families'!$Q:$Q),"")} | O7: =iferror(M7/N7,"") | P7: =iferror(O7/$E7,"") | Q7: =round($D7*P7,2) -> 0 | R7: {=iferror(xlookup($I7,'Product Families'!$A:$A,'Product Families'!$P:$P),"")} -> 0.08 | S7: {=iferror(xlookup($I7,'Product Families'!$A:$A,'Product Families'!$Q:$Q),"")} | T7: =iferror(R7/S7,"") | U7: =iferror(T7/$E7,"") | V7: =round($D7*U7,2) -> 0 | W7: {=iferror(xlookup($J7,'Product Families'!$A:$A,'Product Families'!$P:$P),"")} -> 0.42 | X7: {=iferror(xlookup($J7,'Product Families'!$A:$A,'Product Families'!$Q:$Q),"")} | Y7: =iferror(W7/X7,"") | Z7: =iferror(Y7/$E7,"") | AA7: =round($D7*Z7,2) -> 0 | AB7: {=iferror(xlookup($K7,'Product Families'!$A:$A,'Product Families'!$P:$P),"")} | AC7: {=iferror(xlookup($K7,'Product Families'!$A:$A,'Product Families'!$Q:$Q),"")} | AD7: =iferror(AB7/AC7,"") | AE7: =iferror(AD7/$E7,"") | AF7: =round($D7*AE7,2) -> 0 | AG7: {=iferror(xlookup($L7,'Product Families'!$A:$A,'Product Families'!$P:$P),"")} | AH7: {=iferror(xlookup($L7,'Product Families'!$A:$A,'Product Families'!$Q:$Q),"")} | AI7: =iferror(AG7/AH7,"") | AJ7: =iferror(AI7/$E7,"") | AK7: =round($D7*AJ7,2) -> 0
A8: ACBBG | B8: offline | D8: =iferror(B8/C8,"") | E8: =sum(O8+T8+Y8+AD8+AI8) -> 0 | G8: product not made | H8: ACBBG | M8: {=iferror(xlookup($H8,'Product Families'!$A:$A,'Product Families'!$P:$P),"")} -> 0.44 | N8: {=iferror(xlookup($H8,'Product Families'!$A:$A,'Product Families'!$Q:$Q),"")} | O8: =iferror(M8/N8,"") | P8: =iferror(O8/$E8,"") | Q8: =round($D8*P8,2) -> 0 | R8: {=iferror(xlookup($I8,'Product Families'!$A:$A,'Product Families'!$P:$P),"")} | S8: {=iferror(xlookup($I8,'Product Families'!$A:$A,'Product Families'!$Q:$Q),"")} | T8: =iferror(R8/S8,"") | U8: =iferror(T8/$E8,"") | V8: =round($D8*U8,2) -> 0 | W8: {=iferror(xlookup($J8,'Product Families'!$A:$A,'Product Families'!$P:$P),"")} | X8: {=iferror(xlookup($J8,'Product Families'!$A:$A,'Product Families'!$Q:$Q),"")} | Y8: =iferror(W8/X8,"") | Z8: =iferror(Y8/$E8,"") | AA8: =round($D8*Z8,2) -> 0 | AB8: {=iferror(xlookup($K8,'Product Families'!$A:$A,'Product Families'!$P:$P),"")} | AC8: {=iferror(xlookup($K8,'Product Families'!$A:$A,'Product Families'!$Q:$Q),"")} | AD8: =iferror(AB8/AC8,"") | AE8: =iferror(AD8/$E8,"") | AF8: =round($D8*AE8,2) -> 0 | AG8: {=iferror(xlookup($L8,'Product Families'!$A:$A,'Product Families'!$P:$P),"")} | AH8: {=iferror(xlookup($L8,'Product Families'!$A:$A,'Product Families'!$Q:$Q),"")} | AI8: =iferror(AG8/AH8,"") | AJ8: =iferror(AI8/$E8,"") | AK8: =round($D8*AJ8,2) -> 0
A9: ACBC | B9: 21 | C9: 4 | D9: =iferror(B9/C9,"") -> 5.25 | E9: =sum(O9+T9+Y9+AD9+AI9) -> 0 | H9: ACBC | M9: {=iferror(xlookup($H9,'Product Families'!$A:$A,'Product Families'!$P:$P),"")} -> 0.15 | N9: {=iferror(xlookup($H9,'Product Families'!$A:$A,'Product Families'!$Q:$Q),"")} | O9: =iferror(M9/N9,"") | P9: =iferror(O9/$E9,"") | Q9: =round($D9*P9,2) -> 0 | R9: {=iferror(xlookup($I9,'Product Families'!$A:$A,'Product Families'!$P:$P),"")} | S9: {=iferror(xlookup($I9,'Product Families'!$A:$A,'Product Families'!$Q:$Q),"")} | T9: =iferror(R9/S9,"") | U9: =iferror(T9/$E9,"") | V9: =round($D9*U9,2) -> 0 | W9: {=iferror(xlookup($J9,'Product Families'!$A:$A,'Product Families'!$P:$P),"")} | X9: {=iferror(xlookup($J9,'Product Families'!$A:$A,'Product Families'!$Q:$Q),"")} | Y9: =iferror(W9/X9,"") | Z9: =iferror(Y9/$E9,"") | AA9: =round($D9*Z9,2) -> 0 | AB9: {=iferror(xlookup($K9,'Product Families'!$A:$A,'Product Families'!$P:$P),"")} | AC9: {=iferror(xlookup($K9,'Product Families'!$A:$A,'Product Families'!$Q:$Q),"")} | AD9: =iferror(AB9/AC9,"") | AE9: =iferror(AD9/$E9,"") | AF9: =round($D9*AE9,2) -> 0 | AG9: {=iferror(xlookup($L9,'Product Families'!$A:$A,'Product Families'!$P:$P),"")} | AH9: {=iferror(xlookup($L9,'Product Families'!$A:$A,'Product Families'!$Q:$Q),"")} | AI9: =iferror(AG9/AH9,"") | AJ9: =iferror(AI9/$E9,"") | AK9: =round($D9*AJ9,2) -> 0
A10: ACCLAY | B10: n/a | D10: =iferror(B10/C10,"") | E10: =sum(O10+T10+Y10+AD10+AI10) -> 0 | G10: code not in use | H10: ACCLAY | M10: {=iferror(xlookup($H10,'Product Families'!$A:$A,'Product Families'!$P:$P),"")} -> 0.24 | N10: {=iferror(xlookup($H10,'Product Families'!$A:$A,'Product Families'!$Q:$Q),"")} | O10: =iferror(M10/N10,"") | P10: =iferror(O10/$E10,"") | Q10: =round($D10*P10,2) -> 0 | R10: {=iferror(xlookup($I10,'Product Families'!$A:$A,'Product Families'!$P:$P),"")} | S10: {=iferror(xlookup($I10,'Product Families'!$A:$A,'Product Families'!$Q:$Q),"")} | T10: =iferror(R10/S10,"") | U10: =iferror(T10/$E10,"") | V10: =round($D10*U10,2) -> 0 | W10: {=iferror(xlookup($J10,'Product Families'!$A:$A,'Product Families'!$P:$P),"")} | X10: {=iferror(xlookup($J10,'Product Families'!$A:$A,'Product Families'!$Q:$Q),"")} | Y10: =iferror(W10/X10,"") | Z10: =iferror(Y10/$E10,"") | AA10: =round($D10*Z10,2) -> 0 | AB10: {=iferror(xlookup($K10,'Product Families'!$A:$A,'Product Families'!$P:$P),"")} | AC10: {=iferror(xlookup($K10,'Product Families'!$A:$A,'Product Families'!$Q:$Q),"")} | AD10: =iferror(AB10/AC10,"") | AE10: =iferror(AD10/$E10,"") | AF10: =round($D10*AE10,2) -> 0 | AG10: {=iferror(xlookup($L10,'Product Families'!$A:$A,'Product Families'!$P:$P),"")} | AH10: {=iferror(xlookup($L10,'Product Families'!$A:$A,'Product Families'!$Q:$Q),"")} | AI10: =iferror(AG10/AH10,"") | AJ10: =iferror(AI10/$E10,"") | AK10: =round($D10*AJ10,2) -> 0
A11: ACD | B11: 8.5 | C11: 1 | D11: =iferror(B11/C11,"") -> 8.5 | E11: =sum(O11+T11+Y11+AD11+AI11) -> 0 | H11: ACD | M11: {=iferror(xlookup($H11,'Product Families'!$A:$A,'Product Families'!$P:$P),"")} -> 0.68 | N11: {=iferror(xlookup($H11,'Product Families'!$A:$A,'Product Families'!$Q:$Q),"")} | O11: =iferror(M11/N11,"") | P11: =iferror(O11/$E11,"") | Q11: =round($D11*P11,2) -> 0 | R11: {=iferror(xlookup($I11,'Product Families'!$A:$A,'Product Families'!$P:$P),"")} | S11: {=iferror(xlookup($I11,'Product Families'!$A:$A,'Product Families'!$Q:$Q),"")} | T11: =iferror(R11/S11,"") | U11: =iferror(T11/$E11,"") | V11: =round($D11*U11,2) -> 0 | W11: {=iferror(xlookup($J11,'Product Families'!$A:$A,'Product Families'!$P:$P),"")} | X11: {=iferror(xlookup($J11,'Product Families'!$A:$A,'Product Families'!$Q:$Q),"")} | Y11: =iferror(W11/X11,"") | Z11: =iferror(Y11/$E11,"") | AA11: =round($D11*Z11,2) -> 0 | AB11: {=iferror(xlookup($K11,'Product Families'!$A:$A,'Product Families'!$P:$P),"")} | AC11: {=iferror(xlookup($K11,'Product Families'!$A:$A,'Product Families'!$Q:$Q),"")} | AD11: =iferror(AB11/AC11,"") | AE11: =iferror(AD11/$E11,"") | AF11: =round($D11*AE11,2) -> 0 | AG11: {=iferror(xlookup($L11,'Product Families'!$A:$A,'Product Families'!$P:$P),"")} | AH11: {=iferror(xlookup($L11,'Product Families'!$A:$A,'Product Families'!$Q:$Q),"")} | AI11: =iferror(AG11/AH11,"") | AJ11: =iferror(AI11/$E11,"") | AK11: =round($D11*AJ11,2) -> 0
A12: ACDR | B12: 4 | C12: 1 | D12: =iferror(B12/C12,"") -> 4 | E12: =sum(O12+T12+Y12+AD12+AI12) -> 0 | H12: ACDR | M12: {=iferror(xlookup($H12,'Product Families'!$A:$A,'Product Families'!$P:$P),"")} -> 0.24 | N12: {=iferror(xlookup($H12,'Product Families'!$A:$A,'Product Families'!$Q:$Q),"")} | O12: =iferror(M12/N12,"") | P12: =iferror(O12/$E12,"") | Q12: =round($D12*P12,2) -> 0 | R12: {=iferror(xlookup($I12,'Product Families'!$A:$A,'Product Families'!$P:$P),"")} | S12: {=iferror(xlookup($I12,'Product Families'!$A:$A,'Product Families'!$Q:$Q),"")} | T12: =iferror(R12/S12,"") | U12: =iferror(T12/$E12,"") | V12: =round($D12*U12,2) -> 0 | W12: {=iferror(xlookup($J12,'Product Families'!$A:$A,'Product Families'!$P:$P),"")} | X12: {=iferror(xlookup($J12,'Product Families'!$A:$A,'Product Families'!$Q:$Q),"")} | Y12: =iferror(W12/X12,"") | Z12: =iferror(Y12/$E12,"") | AA12: =round($D12*Z12,2) -> 0 | AB12: {=iferror(xlookup($K12,'Product Families'!$A:$A,'Product Families'!$P:$P),"")} | AC12: {=iferror(xlookup($K12,'Product Families'!$A:$A,'Product Families'!$Q:$Q),"")} | AD12: =iferror(AB12/AC12,"") | AE12: =iferror(AD12/$E12,"") | AF12: =round($D12*AE12,2) -> 0 | AG12: {=iferror(xlookup($L12,'Product Families'!$A:$A,'Product Families'!$P:$P),"")} | AH12: {=iferror(xlookup($L12,'Product Families'!$A:$A,'Product Families'!$Q:$Q),"")} | AI12: =iferror(AG12/AH12,"") | AJ12: =iferror(AI12/$E12,"") | AK12: =round($D12*AJ12,2) -> 0
A13: ACFC | B13: offline | D13: =iferror(B13/C13,"") | E13: =sum(O13+T13+Y13+AD13+AI13) -> 0 | G13: product not made | H13: ACFC | M13: {=iferror(xlookup($H13,'Product Families'!$A:$A,'Product Families'!$P:$P),"")} -> 0.15 | N13: {=iferror(xlookup($H13,'Product Families'!$A:$A,'Product Families'!$Q:$Q),"")} | O13: =iferror(M13/N13,"") | P13: =iferror(O13/$E13,"") | Q13: =round($D13*P13,2) -> 0 | R13: {=iferror(xlookup($I13,'Product Families'!$A:$A,'Product Families'!$P:$P),"")} | S13: {=iferror(xlookup($I13,'Product Families'!$A:$A,'Product Families'!$Q:$Q),"")} | T13: =iferror(R13/S13,"") | U13: =iferror(T13/$E13,"") | V13: =round($D13*U13,2) -> 0 | W13: {=iferror(xlookup($J13,'Product Families'!$A:$A,'Product Families'!$P:$P),"")} | X13: {=iferror(xlookup($J13,'Product Families'!$A:$A,'Product Families'!$Q:$Q),"")} | Y13: =iferror(W13/X13,"") | Z13: =iferror(Y13/$E13,"") | AA13: =round($D13*Z13,2) -> 0 | AB13: {=iferror(xlookup($K13,'Product Families'!$A:$A,'Product Families'!$P:$P),"")} | AC13: {=iferror(xlookup($K13,'Product Families'!$A:$A,'Product Families'!$Q:$Q),"")} | AD13: =iferror(AB13/AC13,"") | AE13: =iferror(AD13/$E13,"") | AF13: =round($D13*AE13,2) -> 0 | AG13: {=iferror(xlookup($L13,'Product Families'!$A:$A,'Product Families'!$P:$P),"")} | AH13: {=iferror(xlookup($L13,'Product Families'!$A:$A,'Product Families'!$Q:$Q),"")} | AI13: =iferror(AG13/AH13,"") | AJ13: =iferror(AI13/$E13,"") | AK13: =round($D13*AJ13,2) -> 0
A14: ACFD | B14: 17.85 | C14: 3 | D14: =iferror(B14/C14,"") -> 5.95 | E14: =sum(O14+T14+Y14+AD14+AI14) -> 0 | H14: ACFD | M14: {=iferror(xlookup($H14,'Product Families'!$A:$A,'Product Families'!$P:$P),"")} -> 0.68 | N14: {=iferror(xlookup($H14,'Product Families'!$A:$A,'Product Families'!$Q:$Q),"")} | O14: =iferror(M14/N14,"") | P14: =iferror(O14/$E14,"") | Q14: =round($D14*P14,2) -> 0 | R14: {=iferror(xlookup($I14,'Product Families'!$A:$A,'Product Families'!$P:$P),"")} | S14: {=iferror(xlookup($I14,'Product Families'!$A:$A,'Product Families'!$Q:$Q),"")} | T14: =iferror(R14/S14,"") | U14: =iferror(T14/$E14,"") | V14: =round($D14*U14,2) -> 0 | W14: {=iferror(xlookup($J14,'Product Families'!$A:$A,'Product Families'!$P:$P),"")} | X14: {=iferror(xlookup($J14,'Product Families'!$A:$A,'Product Families'!$Q:$Q),"")} | Y14: =iferror(W14/X14,"") | Z14: =iferror(Y14/$E14,"") | AA14: =round($D14*Z14,2) -> 0 | AB14: {=iferror(xlookup($K14,'Product Families'!$A:$A,'Product Families'!$P:$P),"")} | AC14: {=iferror(xlookup($K14,'Product Families'!$A:$A,'Product Families'!$Q:$Q),"")} | AD14: =iferror(AB14/AC14,"") | AE14: =iferror(AD14/$E14,"") | AF14: =round($D14*AE14,2) -> 0 | AG14: {=iferror(xlookup($L14,'Product Families'!$A:$A,'Product Families'!$P:$P),"")} | AH14: {=iferror(xlookup($L14,'Product Families'!$A:$A,'Product Families'!$Q:$Q),"")} | AI14: =iferror(AG14/AH14,"") | AJ14: =iferror(AI14/$E14,"") | AK14: =round($D14*AJ14,2) -> 0
A15: ACFM | B15: 12.75 - 19.95 | C15: 4 | D15: =iferror(B15/C15,"") | E15: =sum(O15+T15+Y15+AD15+AI15) -> 0 | G15: 3 different prices | H15: ACFM | M15: {=iferror(xlookup($H15,'Product Families'!$A:$A,'Product Families'!$P:$P),"")} -> 0.29 | N15: {=iferror(xlookup($H15,'Product Families'!$A:$A,'Product Families'!$Q:$Q),"")} | O15: =iferror(M15/N15,"") | P15: =iferror(O15/$E15,"") | Q15: =round($D15*P15,2) -> 0 | R15: {=iferror(xlookup($I15,'Product Families'!$A:$A,'Product Families'!$P:$P),"")} | S15: {=iferror(xlookup($I15,'Product Families'!$A:$A,'Product Families'!$Q:$Q),"")} | T15: =iferror(R15/S15,"") | U15: =iferror(T15/$E15,"") | V15: =round($D15*U15,2) -> 0 | W15: {=iferror(xlookup($J15,'Product Families'!$A:$A,'Product Families'!$P:$P),"")} | X15: {=iferror(xlookup($J15,'Product Families'!$A:$A,'Product Families'!$Q:$Q),"")} | Y15: =iferror(W15/X15,"") | Z15: =iferror(Y15/$E15,"") | AA15: =round($D15*Z15,2) -> 0 | AB15: {=iferror(xlookup($K15,'Product Families'!$A:$A,'Product Families'!$P:$P),"")} | AC15: {=iferror(xlookup($K15,'Product Families'!$A:$A,'Product Families'!$Q:$Q),"")} | AD15: =iferror(AB15/AC15,"") | AE15: =iferror(AD15/$E15,"") | AF15: =round($D15*AE15,2) -> 0 | AG15: {=iferror(xlookup($L15,'Product Families'!$A:$A,'Product Families'!$P:$P),"")} | AH15: {=iferror(xlookup($L15,'Product Families'!$A:$A,'Product Families'!$Q:$Q),"")} | AI15: =iferror(AG15/AH15,"") | AJ15: =iferror(AI15/$E15,"") | AK15: =round($D15*AJ15,2) -> 0
A16: ACGB | B16: n/a | D16: =iferror(B16/C16,"") | E16: =sum(O16+T16+Y16+AD16+AI16) -> 0 | G16: code not in use | H16: ACGB | M16: {=iferror(xlookup($H16,'Product Families'!$A:$A,'Product Families'!$P:$P),"")} -> 0.48 | N16: {=iferror(xlookup($H16,'Product Families'!$A:$A,'Product Families'!$Q:$Q),"")} | O16: =iferror(M16/N16,"") | P16: =iferror(O16/$E16,"") | Q16: =round($D16*P16,2) -> 0 | R16: {=iferror(xlookup($I16,'Product Families'!$A:$A,'Product Families'!$P:$P),"")} | S16: {=iferror(xlookup($I16,'Product Families'!$A:$A,'Product Families'!$Q:$Q),"")} | T16: =iferror(R16/S16,"") | U16: =iferror(T16/$E16,"") | V16: =round($D16*U16,2) -> 0 | W16: {=iferror(xlookup($J16,'Product Families'!$A:$A,'Product Families'!$P:$P),"")} | X16: {=iferror(xlookup($J16,'Product Families'!$A:$A,'Product Families'!$Q:$Q),"")} | Y16: =iferror(W16/X16,"") | Z16: =iferror(Y16/$E16,"") | AA16: =round($D16*Z16,2) -> 0 | AB16: {=iferror(xlookup($K16,'Product Families'!$A:$A,'Product Families'!$P:$P),"")} | AC16: {=iferror(xlookup($K16,'Product Families'!$A:$A,'Product Families'!$Q:$Q),"")} | AD16: =iferror(AB16/AC16,"") | AE16: =iferror(AD16/$E16,"") | AF16: =round($D16*AE16,2) -> 0 | AG16: {=iferror(xlookup($L16,'Product Families'!$A:$A,'Product Families'!$P:$P),"")} | AH16: {=iferror(xlookup($L16,'Product Families'!$A:$A,'Product Families'!$Q:$Q),"")} | AI16: =iferror(AG16/AH16,"") | AJ16: =iferror(AI16/$E16,"") | AK16: =round($D16*AJ16,2) -> 0
A17: ACGP | B17: 11.5 | C17: 1 | D17: =iferror(B17/C17,"") -> 11.5 | E17: =sum(O17+T17+Y17+AD17+AI17) -> 0 | H17: ACGP | M17: {=iferror(xlookup($H17,'Product Families'!$A:$A,'Product Families'!$P:$P),"")} -> 1.15 | N17: {=iferror(xlookup($H17,'Product Families'!$A:$A,'Product Families'!$Q:$Q),"")} | O17: =iferror(M17/N17,"") | P17: =iferror(O17/$E17,"") | Q17: =round($D17*P17,2) -> 0 | R17: {=iferror(xlookup($I17,'Product Families'!$A:$A,'Product Families'!$P:$P),"")} | S17: {=iferror(xlookup($I17,'Product Families'!$A:$A,'Product Families'!$Q:$Q),"")} | T17: =iferror(R17/S17,"") | U17: =iferror(T17/$E17,"") | V17: =round($D17*U17,2) -> 0 | W17: {=iferror(xlookup($J17,'Product Families'!$A:$A,'Product Families'!$P:$P),"")} | X17: {=iferror(xlookup($J17,'Product Families'!$A:$A,'Product Families'!$Q:$Q),"")} | Y17: =iferror(W17/X17,"") | Z17: =iferror(Y17/$E17,"") | AA17: =round($D17*Z17,2) -> 0 | AB17: {=iferror(xlookup($K17,'Product Families'!$A:$A,'Product Families'!$P:$P),"")} | AC17: {=iferror(xlookup($K17,'Product Families'!$A:$A,'Product Families'!$Q:$Q),"")} | AD17: =iferror(AB17/AC17,"") | AE17: =iferror(AD17/$E17,"") | AF17: =round($D17*AE17,2) -> 0 | AG17: {=iferror(xlookup($L17,'Product Families'!$A:$A,'Product Families'!$P:$P),"")} | AH17: {=iferror(xlookup($L17,'Product Families'!$A:$A,'Product Families'!$Q:$Q),"")} | AI17: =iferror(AG17/AH17,"") | AJ17: =iferror(AI17/$E17,"") | AK17: =round($D17*AJ17,2) -> 0
A18: ACGS | B18: 5.95 - 10.50 | C18: 1 | D18: =iferror(B18/C18,"") | E18: =sum(O18+T18+Y18+AD18+AI18) -> 0 | G18: 2 different prices | H18: ACGS | M18: {=iferror(xlookup($H18,'Product Families'!$A:$A,'Product Families'!$P:$P),"")} -> 0.44 | N18: {=iferror(xlookup($H18,'Product Families'!$A:$A,'Product Families'!$Q:$Q),"")} | O18: =iferror(M18/N18,"") | P18: =iferror(O18/$E18,"") | Q18: =round($D18*P18,2) -> 0 | R18: {=iferror(xlookup($I18,'Product Families'!$A:$A,'Product Families'!$P:$P),"")} | S18: {=iferror(xlookup($I18,'Product Families'!$A:$A,'Product Families'!$Q:$Q),"")} | T18: =iferror(R18/S18,"") | U18: =iferror(T18/$E18,"") | V18: =round($D18*U18,2) -> 0 | W18: {=iferror(xlookup($J18,'Product Families'!$A:$A,'Product Families'!$P:$P),"")} | X18: {=iferror(xlookup($J18,'Product Families'!$A:$A,'Product Families'!$Q:$Q),"")} | Y18: =iferror(W18/X18,"") | Z18: =iferror(Y18/$E18,"") | AA18: =round($D18*Z18,2) -> 0 | AB18: {=iferror(xlookup($K18,'Product Families'!$A:$A,'Product Families'!$P:$P),"")} | AC18: {=iferror(xlookup($K18,'Product Families'!$A:$A,'Product Families'!$Q:$Q),"")} | AD18: =iferror(AB18/AC18,"") | AE18: =iferror(AD18/$E18,"") | AF18: =round($D18*AE18,2) -> 0 | AG18: {=iferror(xlookup($L18,'Product Families'!$A:$A,'Product Families'!$P:$P),"")} | AH18: {=iferror(xlookup($L18,'Product Families'!$A:$A,'Product Families'!$Q:$Q),"")} | AI18: =iferror(AG18/AH18,"") | AJ18: =iferror(AI18/$E18,"") | AK18: =round($D18*AJ18,2) -> 0
A19: ACHS | B19: 15.84 | C19: 6 | D19: =iferror(B19/C19,"") -> 2.64 | E19: =sum(O19+T19+Y19+AD19+AI19) -> 0 | G19: Discontinuing | H19: ACHS | I19: ACHSP | M19: {=iferror(xlookup($H19,'Product Families'!$A:$A,'Product Families'!$P:$P),"")} -> 0.18 | N19: {=iferror(xlookup($H19,'Product Families'!$A:$A,'Product Families'!$Q:$Q),"")} | O19: =iferror(M19/N19,"") | P19: =iferror(O19/$E19,"") | Q19: =round($D19*P19,2) -> 0 | R19: {=iferror(xlookup($I19,'Product Families'!$A:$A,'Product Families'!$P:$P),"")} -> 0.22 | S19: {=iferror(xlookup($I19,'Product Families'!$A:$A,'Product Families'!$Q:$Q),"")} | T19: =iferror(R19/S19,"") | U19: =iferror(T19/$E19,"") | V19: =round($D19*U19,2) -> 0 | W19: {=iferror(xlookup($J19,'Product Families'!$A:$A,'Product Families'!$P:$P),"")} | X19: {=iferror(xlookup($J19,'Product Families'!$A:$A,'Product Families'!$Q:$Q),"")} | Y19: =iferror(W19/X19,"") | Z19: =iferror(Y19/$E19,"") | AA19: =round($D19*Z19,2) -> 0 | AB19: {=iferror(xlookup($K19,'Product Families'!$A:$A,'Product Families'!$P:$P),"")} | AC19: {=iferror(xlookup($K19,'Product Families'!$A:$A,'Product Families'!$Q:$Q),"")} | AD19: =iferror(AB19/AC19,"") | AE19: =iferror(AD19/$E19,"") | AF19: =round($D19*AE19,2) -> 0 | AG19: {=iferror(xlookup($L19,'Product Families'!$A:$A,'Product Families'!$P:$P),"")} | AH19: {=iferror(xlookup($L19,'Product Families'!$A:$A,'Product Families'!$Q:$Q),"")} | AI19: =iferror(AG19/AH19,"") | AJ19: =iferror(AI19/$E19,"") | AK19: =round($D19*AJ19,2) -> 0
A20: ACLB | B20: 13.25 | C20: 6 | D20: =iferror(B20/C20,"") -> 2.2083333 | E20: =sum(O20+T20+Y20+AD20+AI20) -> 0 | H20: ACLB | I20: ACLBL | J20: ACLBP | M20: {=iferror(xlookup($H20,'Product Families'!$A:$A,'Product Families'!$P:$P),"")} -> 0.06 | N20: {=iferror(xlookup($H20,'Product Families'!$A:$A,'Product Families'!$Q:$Q),"")} | O20: =iferror(M20/N20,"") | P20: =iferror(O20/$E20,"") | Q20: =round($D20*P20,2) -> 0 | R20: {=iferror(xlookup($I20,'Product Families'!$A:$A,'Product Families'!$P:$P),"")} -> 0.05 | S20: {=iferror(xlookup($I20,'Product Families'!$A:$A,'Product Families'!$Q:$Q),"")} | T20: =iferror(R20/S20,"") | U20: =iferror(T20/$E20,"") | V20: =round($D20*U20,2) -> 0 | W20: {=iferror(xlookup($J20,'Product Families'!$A:$A,'Product Families'!$P:$P),"")} -> 1.07 | X20: {=iferror(xlookup($J20,'Product Families'!$A:$A,'Product Families'!$Q:$Q),"")} | Y20: =iferror(W20/X20,"") | Z20: =iferror(Y20/$E20,"") | AA20: =round($D20*Z20,2) -> 0 | AB20: {=iferror(xlookup($K20,'Product Families'!$A:$A,'Product Families'!$P:$P),"")} | AC20: {=iferror(xlookup($K20,'Product Families'!$A:$A,'Product Families'!$Q:$Q),"")} | AD20: =iferror(AB20/AC20,"") | AE20: =iferror(AD20/$E20,"") | AF20: =round($D20*AE20,2) -> 0 | AG20: {=iferror(xlookup($L20,'Product Families'!$A:$A,'Product Families'!$P:$P),"")} | AH20: {=iferror(xlookup($L20,'Product Families'!$A:$A,'Product Families'!$Q:$Q),"")} | AI20: =iferror(AG20/AH20,"") | AJ20: =iferror(AI20/$E20,"") | AK20: =round($D20*AJ20,2) -> 0
A21: ACOSS | B21: offline | D21: =iferror(B21/C21,"") | E21: =sum(O21+T21+Y21+AD21+AI21) -> 0 | G21: Discontinued | H21: ACOSS | I21: ACOSSP | M21: {=iferror(xlookup($H21,'Product Families'!$A:$A,'Product Families'!$P:$P),"")} -> 0.15 | N21: {=iferror(xlookup($H21,'Product Families'!$A:$A,'Product Families'!$Q:$Q),"")} | O21: =iferror(M21/N21,"") | P21: =iferror(O21/$E21,"") | Q21: =round($D21*P21,2) -> 0 | R21: {=iferror(xlookup($I21,'Product Families'!$A:$A,'Product Families'!$P:$P),"")} -> 0.1 | S21: {=iferror(xlookup($I21,'Product Families'!$A:$A,'Product Families'!$Q:$Q),"")} | T21: =iferror(R21/S21,"") | U21: =iferror(T21/$E21,"") | V21: =round($D21*U21,2) -> 0 | W21: {=iferror(xlookup($J21,'Product Families'!$A:$A,'Product Families'!$P:$P),"")} | X21: {=iferror(xlookup($J21,'Product Families'!$A:$A,'Product Families'!$Q:$Q),"")} | Y21: =iferror(W21/X21,"") | Z21: =iferror(Y21/$E21,"") | AA21: =round($D21*Z21,2) -> 0 | AB21: {=iferror(xlookup($K21,'Product Families'!$A:$A,'Product Families'!$P:$P),"")} | AC21: {=iferror(xlookup($K21,'Product Families'!$A:$A,'Product Families'!$Q:$Q),"")} | AD21: =iferror(AB21/AC21,"") | AE21: =iferror(AD21/$E21,"") | AF21: =round($D21*AE21,2) -> 0 | AG21: {=iferror(xlookup($L21,'Product Families'!$A:$A,'Product Families'!$P:$P),"")} | AH21: {=iferror(xlookup($L21,'Product Families'!$A:$A,'Product Families'!$Q:$Q),"")} | AI21: =iferror(AG21/AH21,"") | AJ21: =iferror(AI21/$E21,"") | AK21: =round($D21*AJ21,2) -> 0
A22: ACREBL | B22: 17.5 | C22: 6 | D22: =iferror(B22/C22,"") -> 2.9166667 | E22: =sum(O22+T22+Y22+AD22+AI22) -> 0 | H22: ACREBL | M22: {=iferror(xlookup($H22,'Product Families'!$A:$A,'Product Families'!$P:$P),"")} -> 0.13 | N22: {=iferror(xlookup($H22,'Product Families'!$A:$A,'Product Families'!$Q:$Q),"")} | O22: =iferror(M22/N22,"") | P22: =iferror(O22/$E22,"") | Q22: =round($D22*P22,2) -> 0 | R22: {=iferror(xlookup($I22,'Product Families'!$A:$A,'Product Families'!$P:$P),"")} | S22: {=iferror(xlookup($I22,'Product Families'!$A:$A,'Product Families'!$Q:$Q),"")} | T22: =iferror(R22/S22,"") | U22: =iferror(T22/$E22,"") | V22: =round($D22*U22,2) -> 0 | W22: {=iferror(xlookup($J22,'Product Families'!$A:$A,'Product Families'!$P:$P),"")} | X22: {=iferror(xlookup($J22,'Product Families'!$A:$A,'Product Families'!$Q:$Q),"")} | Y22: =iferror(W22/X22,"") | Z22: =iferror(Y22/$E22,"") | AA22: =round($D22*Z22,2) -> 0 | AB22: {=iferror(xlookup($K22,'Product Families'!$A:$A,'Product Families'!$P:$P),"")} | AC22: {=iferror(xlookup($K22,'Product Families'!$A:$A,'Product Families'!$Q:$Q),"")} | AD22: =iferror(AB22/AC22,"") | AE22: =iferror(AD22/$E22,"") | AF22: =round($D22*AE22,2) -> 0 | AG22: {=iferror(xlookup($L22,'Product Families'!$A:$A,'Product Families'!$P:$P),"")} | AH22: {=iferror(xlookup($L22,'Product Families'!$A:$A,'Product Families'!$Q:$Q),"")} | AI22: =iferror(AG22/AH22,"") | AJ22: =iferror(AI22/$E22,"") | AK22: =round($D22*AJ22,2) -> 0
A23: ACRM | B23: offline | D23: =iferror(B23/C23,"") | E23: =sum(O23+T23+Y23+AD23+AI23) -> 0 | G23: product not made | H23: ACRM | M23: {=iferror(xlookup($H23,'Product Families'!$A:$A,'Product Families'!$P:$P),"")} -> 0.63 | N23: {=iferror(xlookup($H23,'Product Families'!$A:$A,'Product Families'!$Q:$Q),"")} | O23: =iferror(M23/N23,"") | P23: =iferror(O23/$E23,"") | Q23: =round($D23*P23,2) -> 0 | R23: {=iferror(xlookup($I23,'Product Families'!$A:$A,'Product Families'!$P:$P),"")} | S23: {=iferror(xlookup($I23,'Product Families'!$A:$A,'Product Families'!$Q:$Q),"")} | T23: =iferror(R23/S23,"") | U23: =iferror(T23/$E23,"") | V23: =round($D23*U23,2) -> 0 | W23: {=iferror(xlookup($J23,'Product Families'!$A:$A,'Product Families'!$P:$P),"")} | X23: {=iferror(xlookup($J23,'Product Families'!$A:$A,'Product Families'!$Q:$Q),"")} | Y23: =iferror(W23/X23,"") | Z23: =iferror(Y23/$E23,"") | AA23: =round($D23*Z23,2) -> 0 | AB23: {=iferror(xlookup($K23,'Product Families'!$A:$A,'Product Families'!$P:$P),"")} | AC23: {=iferror(xlookup($K23,'Product Families'!$A:$A,'Product Families'!$Q:$Q),"")} | AD23: =iferror(AB23/AC23,"") | AE23: =iferror(AD23/$E23,"") | AF23: =round($D23*AE23,2) -> 0 | AG23: {=iferror(xlookup($L23,'Product Families'!$A:$A,'Product Families'!$P:$P),"")} | AH23: {=iferror(xlookup($L23,'Product Families'!$A:$A,'Product Families'!$Q:$Q),"")} | AI23: =iferror(AG23/AH23,"") | AJ23: =iferror(AI23/$E23,"") | AK23: =round($D23*AJ23,2) -> 0
A24: ACSaltB | B24: n/a | D24: =iferror(B24/C24,"") | E24: =sum(O24+T24+Y24+AD24+AI24) -> 0 | G24: code not in use | H24: ACSaltB | M24: {=iferror(xlookup($H24,'Product Families'!$A:$A,'Product Families'!$P:$P),"")} -> 1.67 | N24: {=iferror(xlookup($H24,'Product Families'!$A:$A,'Product Families'!$Q:$Q),"")} | O24: =iferror(M24/N24,"") | P24: =iferror(O24/$E24,"") | Q24: =round($D24*P24,2) -> 0 | R24: {=iferror(xlookup($I24,'Product Families'!$A:$A,'Product Families'!$P:$P),"")} | S24: {=iferror(xlookup($I24,'Product Families'!$A:$A,'Product Families'!$Q:$Q),"")} | T24: =iferror(R24/S24,"") | U24: =iferror(T24/$E24,"") | V24: =round($D24*U24,2) -> 0 | W24: {=iferror(xlookup($J24,'Product Families'!$A:$A,'Product Families'!$P:$P),"")} | X24: {=iferror(xlookup($J24,'Product Families'!$A:$A,'Product Families'!$Q:$Q),"")} | Y24: =iferror(W24/X24,"") | Z24: =iferror(Y24/$E24,"") | AA24: =round($D24*Z24,2) -> 0 | AB24: {=iferror(xlookup($K24,'Product Families'!$A:$A,'Product Families'!$P:$P),"")} | AC24: {=iferror(xlookup($K24,'Product Families'!$A:$A,'Product Families'!$Q:$Q),"")} | AD24: =iferror(AB24/AC24,"") | AE24: =iferror(AD24/$E24,"") | AF24: =round($D24*AE24,2) -> 0 | AG24: {=iferror(xlookup($L24,'Product Families'!$A:$A,'Product Families'!$P:$P),"")} | AH24: {=iferror(xlookup($L24,'Product Families'!$A:$A,'Product Families'!$Q:$Q),"")} | AI24: =iferror(AG24/AH24,"") | AJ24: =iferror(AI24/$E24,"") | AK24: =round($D24*AJ24,2) -> 0
A25: ACSample | B25: 5 | C25: 1 | D25: =iferror(B25/C25,"") -> 5 | E25: =sum(O25+T25+Y25+AD25+AI25) -> 0 | G25: old acfp-02 / fragrance sanpmle pack | H25: ACSample | M25: {=iferror(xlookup($H25,'Product Families'!$A:$A,'Product Families'!$P:$P),"")} -> 0.29 | N25: {=iferror(xlookup($H25,'Product Families'!$A:$A,'Product Families'!$Q:$Q),"")} | O25: =iferror(M25/N25,"") | P25: =iferror(O25/$E25,"") | Q25: =round($D25*P25,2) -> 0 | R25: {=iferror(xlookup($I25,'Product Families'!$A:$A,'Product Families'!$P:$P),"")} | S25: {=iferror(xlookup($I25,'Product Families'!$A:$A,'Product Families'!$Q:$Q),"")} | T25: =iferror(R25/S25,"") | U25: =iferror(T25/$E25,"") | V25: =round($D25*U25,2) -> 0 | W25: {=iferror(xlookup($J25,'Product Families'!$A:$A,'Product Families'!$P:$P),"")} | X25: {=iferror(xlookup($J25,'Product Families'!$A:$A,'Product Families'!$Q:$Q),"")} | Y25: =iferror(W25/X25,"") | Z25: =iferror(Y25/$E25,"") | AA25: =round($D25*Z25,2) -> 0 | AB25: {=iferror(xlookup($K25,'Product Families'!$A:$A,'Product Families'!$P:$P),"")} | AC25: {=iferror(xlookup($K25,'Product Families'!$A:$A,'Product Families'!$Q:$Q),"")} | AD25: =iferror(AB25/AC25,"") | AE25: =iferror(AD25/$E25,"") | AF25: =round($D25*AE25,2) -> 0 | AG25: {=iferror(xlookup($L25,'Product Families'!$A:$A,'Product Families'!$P:$P),"")} | AH25: {=iferror(xlookup($L25,'Product Families'!$A:$A,'Product Families'!$Q:$Q),"")} | AI25: =iferror(AG25/AH25,"") | AJ25: =iferror(AI25/$E25,"") | AK25: =round($D25*AJ25,2) -> 0
A26: ACSR | B26: 18.5 | C26: 6 | D26: =iferror(B26/C26,"") -> 3.0833333 | E26: =sum(O26+T26+Y26+AD26+AI26) -> 0 | H26: ACSR | M26: {=iferror(xlookup($H26,'Product Families'!$A:$A,'Product Families'!$P:$P),"")} -> 1.67 | N26: {=iferror(xlookup($H26,'Product Families'!$A:$A,'Product Families'!$Q:$Q),"")} | O26: =iferror(M26/N26,"") | P26: =iferror(O26/$E26,"") | Q26: =round($D26*P26,2) -> 0 | R26: {=iferror(xlookup($I26,'Product Families'!$A:$A,'Product Families'!$P:$P),"")} | S26: {=iferror(xlookup($I26,'Product Families'!$A:$A,'Product Families'!$Q:$Q),"")} | T26: =iferror(R26/S26,"") | U26: =iferror(T26/$E26,"") | V26: =round($D26*U26,2) -> 0 | W26: {=iferror(xlookup($J26,'Product Families'!$A:$A,'Product Families'!$P:$P),"")} | X26: {=iferror(xlookup($J26,'Product Families'!$A:$A,'Product Families'!$Q:$Q),"")} | Y26: =iferror(W26/X26,"") | Z26: =iferror(Y26/$E26,"") | AA26: =round($D26*Z26,2) -> 0 | AB26: {=iferror(xlookup($K26,'Product Families'!$A:$A,'Product Families'!$P:$P),"")} | AC26: {=iferror(xlookup($K26,'Product Families'!$A:$A,'Product Families'!$Q:$Q),"")} | AD26: =iferror(AB26/AC26,"") | AE26: =iferror(AD26/$E26,"") | AF26: =round($D26*AE26,2) -> 0 | AG26: {=iferror(xlookup($L26,'Product Families'!$A:$A,'Product Families'!$P:$P),"")} | AH26: {=iferror(xlookup($L26,'Product Families'!$A:$A,'Product Families'!$Q:$Q),"")} | AI26: =iferror(AG26/AH26,"") | AJ26: =iferror(AI26/$E26,"") | AK26: =round($D26*AJ26,2) -> 0
A27: ACSRB | B27: n/a | D27: =iferror(B27/C27,"") | E27: =sum(O27+T27+Y27+AD27+AI27) -> 0 | G27: Made with the Beast | H27: ACSRB | M27: {=iferror(xlookup($H27,'Product Families'!$A:$A,'Product Families'!$P:$P),"")} -> 0.21 | N27: {=iferror(xlookup($H27,'Product Families'!$A:$A,'Product Families'!$Q:$Q),"")} | O27: =iferror(M27/N27,"") | P27: =iferror(O27/$E27,"") | Q27: =round($D27*P27,2) -> 0 | R27: {=iferror(xlookup($I27,'Product Families'!$A:$A,'Product Families'!$P:$P),"")} | S27: {=iferror(xlookup($I27,'Product Families'!$A:$A,'Product Families'!$Q:$Q),"")} | T27: =iferror(R27/S27,"") | U27: =iferror(T27/$E27,"") | V27: =round($D27*U27,2) -> 0 | W27: {=iferror(xlookup($J27,'Product Families'!$A:$A,'Product Families'!$P:$P),"")} | X27: {=iferror(xlookup($J27,'Product Families'!$A:$A,'Product Families'!$Q:$Q),"")} | Y27: =iferror(W27/X27,"") | Z27: =iferror(Y27/$E27,"") | AA27: =round($D27*Z27,2) -> 0 | AB27: {=iferror(xlookup($K27,'Product Families'!$A:$A,'Product Families'!$P:$P),"")} | AC27: {=iferror(xlookup($K27,'Product Families'!$A:$A,'Product Families'!$Q:$Q),"")} | AD27: =iferror(AB27/AC27,"") | AE27: =iferror(AD27/$E27,"") | AF27: =round($D27*AE27,2) -> 0 | AG27: {=iferror(xlookup($L27,'Product Families'!$A:$A,'Product Families'!$P:$P),"")} | AH27: {=iferror(xlookup($L27,'Product Families'!$A:$A,'Product Families'!$Q:$Q),"")} | AI27: =iferror(AG27/AH27,"") | AJ27: =iferror(AI27/$E27,"") | AK27: =round($D27*AJ27,2) -> 0
A28: ACSS | B28: 15.5 | C28: 4 | D28: =iferror(B28/C28,"") -> 3.875 | E28: =sum(O28+T28+Y28+AD28+AI28) -> 0 | H28: ACSS | M28: {=iferror(xlookup($H28,'Product Families'!$A:$A,'Product Families'!$P:$P),"")} -> 0.44 | N28: {=iferror(xlookup($H28,'Product Families'!$A:$A,'Product Families'!$Q:$Q),"")} | O28: =iferror(M28/N28,"") | P28: =iferror(O28/$E28,"") | Q28: =round($D28*P28,2) -> 0 | R28: {=iferror(xlookup($I28,'Product Families'!$A:$A,'Product Families'!$P:$P),"")} | S28: {=iferror(xlookup($I28,'Product Families'!$A:$A,'Product Families'!$Q:$Q),"")} | T28: =iferror(R28/S28,"") | U28: =iferror(T28/$E28,"") | V28: =round($D28*U28,2) -> 0 | W28: {=iferror(xlookup($J28,'Product Families'!$A:$A,'Product Families'!$P:$P),"")} | X28: {=iferror(xlookup($J28,'Product Families'!$A:$A,'Product Families'!$Q:$Q),"")} | Y28: =iferror(W28/X28,"") | Z28: =iferror(Y28/$E28,"") | AA28: =round($D28*Z28,2) -> 0 | AB28: {=iferror(xlookup($K28,'Product Families'!$A:$A,'Product Families'!$P:$P),"")} | AC28: {=iferror(xlookup($K28,'Product Families'!$A:$A,'Product Families'!$Q:$Q),"")} | AD28: =iferror(AB28/AC28,"") | AE28: =iferror(AD28/$E28,"") | AF28: =round($D28*AE28,2) -> 0 | AG28: {=iferror(xlookup($L28,'Product Families'!$A:$A,'Product Families'!$P:$P),"")} | AH28: {=iferror(xlookup($L28,'Product Families'!$A:$A,'Product Families'!$Q:$Q),"")} | AI28: =iferror(AG28/AH28,"") | AJ28: =iferror(AI28/$E28,"") | AK28: =round($D28*AJ28,2) -> 0
A29: ACTEP | B29: 18 | C29: 3 | D29: =iferror(B29/C29,"") -> 6 | E29: =sum(O29+T29+Y29+AD29+AI29) -> 0 | H29: ACTEP | M29: {=iferror(xlookup($H29,'Product Families'!$A:$A,'Product Families'!$P:$P),"")} -> 0.44 | N29: {=iferror(xlookup($H29,'Product Families'!$A:$A,'Product Families'!$Q:$Q),"")} | O29: =iferror(M29/N29,"") | P29: =iferror(O29/$E29,"") | Q29: =round($D29*P29,2) -> 0 | R29: {=iferror(xlookup($I29,'Product Families'!$A:$A,'Product Families'!$P:$P),"")} | S29: {=iferror(xlookup($I29,'Product Families'!$A:$A,'Product Families'!$Q:$Q),"")} | T29: =iferror(R29/S29,"") | U29: =iferror(T29/$E29,"") | V29: =round($D29*U29,2) -> 0 | W29: {=iferror(xlookup($J29,'Product Families'!$A:$A,'Product Families'!$P:$P),"")} | X29: {=iferror(xlookup($J29,'Product Families'!$A:$A,'Product Families'!$Q:$Q),"")} | Y29: =iferror(W29/X29,"") | Z29: =iferror(Y29/$E29,"") | AA29: =round($D29*Z29,2) -> 0 | AB29: {=iferror(xlookup($K29,'Product Families'!$A:$A,'Product Families'!$P:$P),"")} | AC29: {=iferror(xlookup($K29,'Product Families'!$A:$A,'Product Families'!$Q:$Q),"")} | AD29: =iferror(AB29/AC29,"") | AE29: =iferror(AD29/$E29,"") | AF29: =round($D29*AE29,2) -> 0 | AG29: {=iferror(xlookup($L29,'Product Families'!$A:$A,'Product Families'!$P:$P),"")} | AH29: {=iferror(xlookup($L29,'Product Families'!$A:$A,'Product Families'!$Q:$Q),"")} | AI29: =iferror(AG29/AH29,"") | AJ29: =iferror(AI29/$E29,"") | AK29: =round($D29*AJ29,2) -> 0
A30: ACWM | B30: 16 | C30: 4 | D30: =iferror(B30/C30,"") -> 4 | E30: =sum(O30+T30+Y30+AD30+AI30) -> 0 | H30: ACWM | M30: {=iferror(xlookup($H30,'Product Families'!$A:$A,'Product Families'!$P:$P),"")} -> 0.44 | N30: {=iferror(xlookup($H30,'Product Families'!$A:$A,'Product Families'!$Q:$Q),"")} | O30: =iferror(M30/N30,"") | P30: =iferror(O30/$E30,"") | Q30: =round($D30*P30,2) -> 0 | R30: {=iferror(xlookup($I30,'Product Families'!$A:$A,'Product Families'!$P:$P),"")} | S30: {=iferror(xlookup($I30,'Product Families'!$A:$A,'Product Families'!$Q:$Q),"")} | T30: =iferror(R30/S30,"") | U30: =iferror(T30/$E30,"") | V30: =round($D30*U30,2) -> 0 | W30: {=iferror(xlookup($J30,'Product Families'!$A:$A,'Product Families'!$P:$P),"")} | X30: {=iferror(xlookup($J30,'Product Families'!$A:$A,'Product Families'!$Q:$Q),"")} | Y30: =iferror(W30/X30,"") | Z30: =iferror(Y30/$E30,"") | AA30: =round($D30*Z30,2) -> 0 | AB30: {=iferror(xlookup($K30,'Product Families'!$A:$A,'Product Families'!$P:$P),"")} | AC30: {=iferror(xlookup($K30,'Product Families'!$A:$A,'Product Families'!$Q:$Q),"")} | AD30: =iferror(AB30/AC30,"") | AE30: =iferror(AD30/$E30,"") | AF30: =round($D30*AE30,2) -> 0 | AG30: {=iferror(xlookup($L30,'Product Families'!$A:$A,'Product Families'!$P:$P),"")} | AH30: {=iferror(xlookup($L30,'Product Families'!$A:$A,'Product Families'!$Q:$Q),"")} | AI30: =iferror(AG30/AH30,"") | AJ30: =iferror(AI30/$E30,"") | AK30: =round($D30*AJ30,2) -> 0
A31: AHBL | B31: 16.32 | C31: 4 | D31: =iferror(B31/C31,"") -> 4.08 | E31: =sum(O31+T31+Y31+AD31+AI31) -> 0 | M31: {=iferror(xlookup($H31,'Product Families'!$A:$A,'Product Families'!$P:$P),"")} | N31: {=iferror(xlookup($H31,'Product Families'!$A:$A,'Product Families'!$Q:$Q),"")} | O31: =iferror(M31/N31,"") | P31: =iferror(O31/$E31,"") | Q31: =round($D31*P31,2) -> 0 | R31: {=iferror(xlookup($I31,'Product Families'!$A:$A,'Product Families'!$P:$P),"")} | S31: {=iferror(xlookup($I31,'Product Families'!$A:$A,'Product Families'!$Q:$Q),"")} | T31: =iferror(R31/S31,"") | U31: =iferror(T31/$E31,"") | V31: =round($D31*U31,2) -> 0 | W31: {=iferror(xlookup($J31,'Product Families'!$A:$A,'Product Families'!$P:$P),"")} | X31: {=iferror(xlookup($J31,'Product Families'!$A:$A,'Product Families'!$Q:$Q),"")} | Y31: =iferror(W31/X31,"") | Z31: =iferror(Y31/$E31,"") | AA31: =round($D31*Z31,2) -> 0 | AB31: {=iferror(xlookup($K31,'Product Families'!$A:$A,'Product Families'!$P:$P),"")} | AC31: {=iferror(xlookup($K31,'Product Families'!$A:$A,'Product Families'!$Q:$Q),"")} | AD31: =iferror(AB31/AC31,"") | AE31: =iferror(AD31/$E31,"") | AF31: =round($D31*AE31,2) -> 0 | AG31: {=iferror(xlookup($L31,'Product Families'!$A:$A,'Product Families'!$P:$P),"")} | AH31: {=iferror(xlookup($L31,'Product Families'!$A:$A,'Product Families'!$Q:$Q),"")} | AI31: =iferror(AG31/AH31,"") | AJ31: =iferror(AI31/$E31,"") | AK31: =round($D31*AJ31,2) -> 0
A32: AHBLP | B32: n/a | D32: =iferror(B32/C32,"") | E32: =sum(O32+T32+Y32+AD32+AI32) -> 0 | G32: code not in use | M32: {=iferror(xlookup($H32,'Product Families'!$A:$A,'Product Families'!$P:$P),"")} | N32: {=iferror(xlookup($H32,'Product Families'!$A:$A,'Product Families'!$Q:$Q),"")} | O32: =iferror(M32/N32,"") | P32: =iferror(O32/$E32,"") | Q32: =round($D32*P32,2) -> 0 | R32: {=iferror(xlookup($I32,'Product Families'!$A:$A,'Product Families'!$P:$P),"")} | S32: {=iferror(xlookup($I32,'Product Families'!$A:$A,'Product Families'!$Q:$Q),"")} | T32: =iferror(R32/S32,"") | U32: =iferror(T32/$E32,"") | V32: =round($D32*U32,2) -> 0 | W32: {=iferror(xlookup($J32,'Product Families'!$A:$A,'Product Families'!$P:$P),"")} | X32: {=iferror(xlookup($J32,'Product Families'!$A:$A,'Product Families'!$Q:$Q),"")} | Y32: =iferror(W32/X32,"") | Z32: =iferror(Y32/$E32,"") | AA32: =round($D32*Z32,2) -> 0 | AB32: {=iferror(xlookup($K32,'Product Families'!$A:$A,'Product Families'!$P:$P),"")} | AC32: {=iferror(xlookup($K32,'Product Families'!$A:$A,'Product Families'!$Q:$Q),"")} | AD32: =iferror(AB32/AC32,"") | AE32: =iferror(AD32/$E32,"") | AF32: =round($D32*AE32,2) -> 0 | AG32: {=iferror(xlookup($L32,'Product Families'!$A:$A,'Product Families'!$P:$P),"")} | AH32: {=iferror(xlookup($L32,'Product Families'!$A:$A,'Product Families'!$Q:$Q),"")} | AI32: =iferror(AG32/AH32,"") | AJ32: =iferror(AI32/$E32,"") | AK32: =round($D32*AJ32,2) -> 0
A33: AHBLC | B33: n/a | D33: =iferror(B33/C33,"") | E33: =sum(O33+T33+Y33+AD33+AI33) -> 0 | G33: code not in use | M33: {=iferror(xlookup($H33,'Product Families'!$A:$A,'Product Families'!$P:$P),"")} | N33: {=iferror(xlookup($H33,'Product Families'!$A:$A,'Product Families'!$Q:$Q),"")} | O33: =iferror(M33/N33,"") | P33: =iferror(O33/$E33,"") | Q33: =round($D33*P33,2) -> 0 | R33: {=iferror(xlookup($I33,'Product Families'!$A:$A,'Product Families'!$P:$P),"")} | S33: {=iferror(xlookup($I33,'Product Families'!$A:$A,'Product Families'!$Q:$Q),"")} | T33: =iferror(R33/S33,"") | U33: =iferror(T33/$E33,"") | V33: =round($D33*U33,2) -> 0 | W33: {=iferror(xlookup($J33,'Product Families'!$A:$A,'Product Families'!$P:$P),"")} | X33: {=iferror(xlookup($J33,'Product Families'!$A:$A,'Product Families'!$Q:$Q),"")} | Y33: =iferror(W33/X33,"") | Z33: =iferror(Y33/$E33,"") | AA33: =round($D33*Z33,2) -> 0 | AB33: {=iferror(xlookup($K33,'Product Families'!$A:$A,'Product Families'!$P:$P),"")} | AC33: {=iferror(xlookup($K33,'Product Families'!$A:$A,'Product Families'!$Q:$Q),"")} | AD33: =iferror(AB33/AC33,"") | AE33: =iferror(AD33/$E33,"") | AF33: =round($D33*AE33,2) -> 0 | AG33: {=iferror(xlookup($L33,'Product Families'!$A:$A,'Product Families'!$P:$P),"")} | AH33: {=iferror(xlookup($L33,'Product Families'!$A:$A,'Product Families'!$Q:$Q),"")} | AI33: =iferror(AG33/AH33,"") | AJ33: =iferror(AI33/$E33,"") | AK33: =round($D33*AJ33,2) -> 0
A34: AHBLUL | B34: 16.32 | C34: 4 | D34: =iferror(B34/C34,"") -> 4.08 | E34: =sum(O34+T34+Y34+AD34+AI34) -> 0 | M34: {=iferror(xlookup($H34,'Product Families'!$A:$A,'Product Families'!$P:$P),"")} | N34: {=iferror(xlookup($H34,'Product Families'!$A:$A,'Product Families'!$Q:$Q),"")} | O34: =iferror(M34/N34,"") | P34: =iferror(O34/$E34,"") | Q34: =round($D34*P34,2) -> 0 | R34: {=iferror(xlookup($I34,'Product Families'!$A:$A,'Product Families'!$P:$P),"")} | S34: {=iferror(xlookup($I34,'Product Families'!$A:$A,'Product Families'!$Q:$Q),"")} | T34: =iferror(R34/S34,"") | U34: =iferror(T34/$E34,"") | V34: =round($D34*U34,2) -> 0 | W34: {=iferror(xlookup($J34,'Product Families'!$A:$A,'Product Families'!$P:$P),"")} | X34: {=iferror(xlookup($J34,'Product Families'!$A:$A,'Product Families'!$Q:$Q),"")} | Y34: =iferror(W34/X34,"") | Z34: =iferror(Y34/$E34,"") | AA34: =round($D34*Z34,2) -> 0 | AB34: {=iferror(xlookup($K34,'Product Families'!$A:$A,'Product Families'!$P:$P),"")} | AC34: {=iferror(xlookup($K34,'Product Families'!$A:$A,'Product Families'!$Q:$Q),"")} | AD34: =iferror(AB34/AC34,"") | AE34: =iferror(AD34/$E34,"") | AF34: =round($D34*AE34,2) -> 0 | AG34: {=iferror(xlookup($L34,'Product Families'!$A:$A,'Product Families'!$P:$P),"")} | AH34: {=iferror(xlookup($L34,'Product Families'!$A:$A,'Product Families'!$Q:$Q),"")} | AI34: =iferror(AG34/AH34,"") | AJ34: =iferror(AI34/$E34,"") | AK34: =round($D34*AJ34,2) -> 0
A35: AHBW | B35: 14.84 | C35: 4 | D35: =iferror(B35/C35,"") -> 3.71 | E35: =sum(O35+T35+Y35+AD35+AI35) -> 0 | M35: {=iferror(xlookup($H35,'Product Families'!$A:$A,'Product Families'!$P:$P),"")} | N35: {=iferror(xlookup($H35,'Product Families'!$A:$A,'Product Families'!$Q:$Q),"")} | O35: =iferror(M35/N35,"") | P35: =iferror(O35/$E35,"") | Q35: =round($D35*P35,2) -> 0 | R35: {=iferror(xlookup($I35,'Product Families'!$A:$A,'Product Families'!$P:$P),"")} | S35: {=iferror(xlookup($I35,'Product Families'!$A:$A,'Product Families'!$Q:$Q),"")} | T35: =iferror(R35/S35,"") | U35: =iferror(T35/$E35,"") | V35: =round($D35*U35,2) -> 0 | W35: {=iferror(xlookup($J35,'Product Families'!$A:$A,'Product Families'!$P:$P),"")} | X35: {=iferror(xlookup($J35,'Product Families'!$A:$A,'Product Families'!$Q:$Q),"")} | Y35: =iferror(W35/X35,"") | Z35: =iferror(Y35/$E35,"") | AA35: =round($D35*Z35,2) -> 0 | AB35: {=iferror(xlookup($K35,'Product Families'!$A:$A,'Product Families'!$P:$P),"")} | AC35: {=iferror(xlookup($K35,'Product Families'!$A:$A,'Product Families'!$Q:$Q),"")} | AD35: =iferror(AB35/AC35,"") | AE35: =iferror(AD35/$E35,"") | AF35: =round($D35*AE35,2) -> 0 | AG35: {=iferror(xlookup($L35,'Product Families'!$A:$A,'Product Families'!$P:$P),"")} | AH35: {=iferror(xlookup($L35,'Product Families'!$A:$A,'Product Families'!$Q:$Q),"")} | AI35: =iferror(AG35/AH35,"") | AJ35: =iferror(AI35/$E35,"") | AK35: =round($D35*AJ35,2) -> 0
A36: AHBWB | B36: 25.13 | C36: 1 | D36: =iferror(B36/C36,"") -> 25.13 | E36: =sum(O36+T36+Y36+AD36+AI36) -> 0 | M36: {=iferror(xlookup($H36,'Product Families'!$A:$A,'Product Families'!$P:$P),"")} | N36: {=iferror(xlookup($H36,'Product Families'!$A:$A,'Product Families'!$Q:$Q),"")} | O36: =iferror(M36/N36,"") | P36: =iferror(O36/$E36,"") | Q36: =round($D36*P36,2) -> 0 | R36: {=iferror(xlookup($I36,'Product Families'!$A:$A,'Product Families'!$P:$P),"")} | S36: {=iferror(xlookup($I36,'Product Families'!$A:$A,'Product Families'!$Q:$Q),"")} | T36: =iferror(R36/S36,"") | U36: =iferror(T36/$E36,"") | V36: =round($D36*U36,2) -> 0 | W36: {=iferror(xlookup($J36,'Product Families'!$A:$A,'Product Families'!$P:$P),"")} | X36: {=iferror(xlookup($J36,'Product Families'!$A:$A,'Product Families'!$Q:$Q),"")} | Y36: =iferror(W36/X36,"") | Z36: =iferror(Y36/$E36,"") | AA36: =round($D36*Z36,2) -> 0 | AB36: {=iferror(xlookup($K36,'Product Families'!$A:$A,'Product Families'!$P:$P),"")} | AC36: {=iferror(xlookup($K36,'Product Families'!$A:$A,'Product Families'!$Q:$Q),"")} | AD36: =iferror(AB36/AC36,"") | AE36: =iferror(AD36/$E36,"") | AF36: =round($D36*AE36,2) -> 0 | AG36: {=iferror(xlookup($L36,'Product Families'!$A:$A,'Product Families'!$P:$P),"")} | AH36: {=iferror(xlookup($L36,'Product Families'!$A:$A,'Product Families'!$Q:$Q),"")} | AI36: =iferror(AG36/AH36,"") | AJ36: =iferror(AI36/$E36,"") | AK36: =round($D36*AJ36,2) -> 0
A37: AHBWP | B37: n/a | D37: =iferror(B37/C37,"") | E37: =sum(O37+T37+Y37+AD37+AI37) -> 0 | G37: code not in use | M37: {=iferror(xlookup($H37,'Product Families'!$A:$A,'Product Families'!$P:$P),"")} | N37: {=iferror(xlookup($H37,'Product Families'!$A:$A,'Product Families'!$Q:$Q),"")} | O37: =iferror(M37/N37,"") | P37: =iferror(O37/$E37,"") | Q37: =round($D37*P37,2) -> 0 | R37: {=iferror(xlookup($I37,'Product Families'!$A:$A,'Product Families'!$P:$P),"")} | S37: {=iferror(xlookup($I37,'Product Families'!$A:$A,'Product Families'!$Q:$Q),"")} | T37: =iferror(R37/S37,"") | U37: =iferror(T37/$E37,"") | V37: =round($D37*U37,2) -> 0 | W37: {=iferror(xlookup($J37,'Product Families'!$A:$A,'Product Families'!$P:$P),"")} | X37: {=iferror(xlookup($J37,'Product Families'!$A:$A,'Product Families'!$Q:$Q),"")} | Y37: =iferror(W37/X37,"") | Z37: =iferror(Y37/$E37,"") | AA37: =round($D37*Z37,2) -> 0 | AB37: {=iferror(xlookup($K37,'Product Families'!$A:$A,'Product Families'!$P:$P),"")} | AC37: {=iferror(xlookup($K37,'Product Families'!$A:$A,'Product Families'!$Q:$Q),"")} | AD37: =iferror(AB37/AC37,"") | AE37: =iferror(AD37/$E37,"") | AF37: =round($D37*AE37,2) -> 0 | AG37: {=iferror(xlookup($L37,'Product Families'!$A:$A,'Product Families'!$P:$P),"")} | AH37: {=iferror(xlookup($L37,'Product Families'!$A:$A,'Product Families'!$Q:$Q),"")} | AI37: =iferror(AG37/AH37,"") | AJ37: =iferror(AI37/$E37,"") | AK37: =round($D37*AJ37,2) -> 0
A38: AHBWUL | B38: 14.84 | C38: 4 | D38: =iferror(B38/C38,"") -> 3.71 | E38: =sum(O38+T38+Y38+AD38+AI38) -> 0 | M38: {=iferror(xlookup($H38,'Product Families'!$A:$A,'Product Families'!$P:$P),"")} | N38: {=iferror(xlookup($H38,'Product Families'!$A:$A,'Product Families'!$Q:$Q),"")} | O38: =iferror(M38/N38,"") | P38: =iferror(O38/$E38,"") | Q38: =round($D38*P38,2) -> 0 | R38: {=iferror(xlookup($I38,'Product Families'!$A:$A,'Product Families'!$P:$P),"")} | S38: {=iferror(xlookup($I38,'Product Families'!$A:$A,'Product Families'!$Q:$Q),"")} | T38: =iferror(R38/S38,"") | U38: =iferror(T38/$E38,"") | V38: =round($D38*U38,2) -> 0 | W38: {=iferror(xlookup($J38,'Product Families'!$A:$A,'Product Families'!$P:$P),"")} | X38: {=iferror(xlookup($J38,'Product Families'!$A:$A,'Product Families'!$Q:$Q),"")} | Y38: =iferror(W38/X38,"") | Z38: =iferror(Y38/$E38,"") | AA38: =round($D38*Z38,2) -> 0 | AB38: {=iferror(xlookup($K38,'Product Families'!$A:$A,'Product Families'!$P:$P),"")} | AC38: {=iferror(xlookup($K38,'Product Families'!$A:$A,'Product Families'!$Q:$Q),"")} | AD38: =iferror(AB38/AC38,"") | AE38: =iferror(AD38/$E38,"") | AF38: =round($D38*AE38,2) -> 0 | AG38: {=iferror(xlookup($L38,'Product Families'!$A:$A,'Product Families'!$P:$P),"")} | AH38: {=iferror(xlookup($L38,'Product Families'!$A:$A,'Product Families'!$Q:$Q),"")} | AI38: =iferror(AG38/AH38,"") | AJ38: =iferror(AI38/$E38,"") | AK38: =round($D38*AJ38,2) -> 0
A39: AHBWULC | B39: n/a | D39: =iferror(B39/C39,"") | E39: =sum(O39+T39+Y39+AD39+AI39) -> 0 | G39: code not in use | M39: {=iferror(xlookup($H39,'Product Families'!$A:$A,'Product Families'!$P:$P),"")} | N39: {=iferror(xlookup($H39,'Product Families'!$A:$A,'Product Families'!$Q:$Q),"")} | O39: =iferror(M39/N39,"") | P39: =iferror(O39/$E39,"") | Q39: =round($D39*P39,2) -> 0 | R39: {=iferror(xlookup($I39,'Product Families'!$A:$A,'Product Families'!$P:$P),"")} | S39: {=iferror(xlookup($I39,'Product Families'!$A:$A,'Product Families'!$Q:$Q),"")} | T39: =iferror(R39/S39,"") | U39: =iferror(T39/$E39,"") | V39: =round($D39*U39,2) -> 0 | W39: {=iferror(xlookup($J39,'Product Families'!$A:$A,'Product Families'!$P:$P),"")} | X39: {=iferror(xlookup($J39,'Product Families'!$A:$A,'Product Families'!$Q:$Q),"")} | Y39: =iferror(W39/X39,"") | Z39: =iferror(Y39/$E39,"") | AA39: =round($D39*Z39,2) -> 0 | AB39: {=iferror(xlookup($K39,'Product Families'!$A:$A,'Product Families'!$P:$P),"")} | AC39: {=iferror(xlookup($K39,'Product Families'!$A:$A,'Product Families'!$Q:$Q),"")} | AD39: =iferror(AB39/AC39,"") | AE39: =iferror(AD39/$E39,"") | AF39: =round($D39*AE39,2) -> 0 | AG39: {=iferror(xlookup($L39,'Product Families'!$A:$A,'Product Families'!$P:$P),"")} | AH39: {=iferror(xlookup($L39,'Product Families'!$A:$A,'Product Families'!$Q:$Q),"")} | AI39: =iferror(AG39/AH39,"") | AJ39: =iferror(AI39/$E39,"") | AK39: =round($D39*AJ39,2) -> 0
A40: AHBLC | B40: n/a | D40: =iferror(B40/C40,"") | E40: =sum(O40+T40+Y40+AD40+AI40) -> 0 | G40: code not in use | M40: {=iferror(xlookup($H40,'Product Families'!$A:$A,'Product Families'!$P:$P),"")} | N40: {=iferror(xlookup($H40,'Product Families'!$A:$A,'Product Families'!$Q:$Q),"")} | O40: =iferror(M40/N40,"") | P40: =iferror(O40/$E40,"") | Q40: =round($D40*P40,2) -> 0 | R40: {=iferror(xlookup($I40,'Product Families'!$A:$A,'Product Families'!$P:$P),"")} | S40: {=iferror(xlookup($I40,'Product Families'!$A:$A,'Product Families'!$Q:$Q),"")} | T40: =iferror(R40/S40,"") | U40: =iferror(T40/$E40,"") | V40: =round($D40*U40,2) -> 0 | W40: {=iferror(xlookup($J40,'Product Families'!$A:$A,'Product Families'!$P:$P),"")} | X40: {=iferror(xlookup($J40,'Product Families'!$A:$A,'Product Families'!$Q:$Q),"")} | Y40: =iferror(W40/X40,"") | Z40: =iferror(Y40/$E40,"") | AA40: =round($D40*Z40,2) -> 0 | AB40: {=iferror(xlookup($K40,'Product Families'!$A:$A,'Product Families'!$P:$P),"")} | AC40: {=iferror(xlookup($K40,'Product Families'!$A:$A,'Product Families'!$Q:$Q),"")} | AD40: =iferror(AB40/AC40,"") | AE40: =iferror(AD40/$E40,"") | AF40: =round($D40*AE40,2) -> 0 | AG40: {=iferror(xlookup($L40,'Product Families'!$A:$A,'Product Families'!$P:$P),"")} | AH40: {=iferror(xlookup($L40,'Product Families'!$A:$A,'Product Families'!$Q:$Q),"")} | AI40: =iferror(AG40/AH40,"") | AJ40: =iferror(AI40/$E40,"") | AK40: =round($D40*AJ40,2) -> 0
...

Sheet Wholesale Earnings
B1: Totals
A2: Name | B2: Week 1 | C2: Week 2 | D2: Week 3 | E2: Week 4 | F2: Week 5
A3: Audrey Migliaccio | B3: =sumif('Week 1 - Making'!$A:$A,$A3,'Week 1 - Making'!$Y:$Y) -> 0 | C3: =sumif('Week 2 - Making'!$A:$A,$A3,'Week 2 - Making'!$Y:$Y) -> 0 | D3: =sumif('Week 3 - Making'!$A:$A,$A3,'Week 3 - Making'!$Y:$Y) -> 0 | E3: =sumif('Week 4 - Making'!$A:$A,$A3,'Week 4 - Making'!$Y:$Y) -> 0 | F3: =sumif('Week 5 - Making'!$A:$A,$A3,'Week 5 - Making'!$Y:$Y) -> 0
A4: Filip Kurinec | B4: =sumif('Week 1 - Making'!$A:$A,$A4,'Week 1 - Making'!$Y:$Y) -> 0 | C4: =sumif('Week 2 - Making'!$A:$A,$A4,'Week 2 - Making'!$Y:$Y) -> 0 | D4: =sumif('Week 3 - Making'!$A:$A,$A4,'Week 3 - Making'!$Y:$Y) -> 0 | E4: =sumif('Week 4 - Making'!$A:$A,$A4,'Week 4 - Making'!$Y:$Y) -> 0 | F4: =sumif('Week 5 - Making'!$A:$A,$A4,'Week 5 - Making'!$Y:$Y) -> 0
A5: Georgeta Videanu | B5: =sumif('Week 1 - Making'!$A:$A,$A5,'Week 1 - Making'!$Y:$Y) -> 0 | C5: =sumif('Week 2 - Making'!$A:$A,$A5,'Week 2 - Making'!$Y:$Y) -> 0 | D5: =sumif('Week 3 - Making'!$A:$A,$A5,'Week 3 - Making'!$Y:$Y) -> 0 | E5: =sumif('Week 4 - Making'!$A:$A,$A5,'Week 4 - Making'!$Y:$Y) -> 0 | F5: =sumif('Week 5 - Making'!$A:$A,$A5,'Week 5 - Making'!$Y:$Y) -> 0
A6: Gheorghe Hutu | B6: =sumif('Week 1 - Making'!$A:$A,$A6,'Week 1 - Making'!$Y:$Y) -> 1893.43 | C6: =sumif('Week 2 - Making'!$A:$A,$A6,'Week 2 - Making'!$Y:$Y) -> 1466.08 | D6: =sumif('Week 3 - Making'!$A:$A,$A6,'Week 3 - Making'!$Y:$Y) -> 0 | E6: =sumif('Week 4 - Making'!$A:$A,$A6,'Week 4 - Making'!$Y:$Y) -> 0 | F6: =sumif('Week 5 - Making'!$A:$A,$A6,'Week 5 - Making'!$Y:$Y) -> 0
A7: Gintare Grimalauskiene | B7: =sumif('Week 1 - Making'!$A:$A,$A7,'Week 1 - Making'!$Y:$Y) -> 0 | C7: =sumif('Week 2 - Making'!$A:$A,$A7,'Week 2 - Making'!$Y:$Y) -> 0 | D7: =sumif('Week 3 - Making'!$A:$A,$A7,'Week 3 - Making'!$Y:$Y) -> 0 | E7: =sumif('Week 4 - Making'!$A:$A,$A7,'Week 4 - Making'!$Y:$Y) -> 0 | F7: =sumif('Week 5 - Making'!$A:$A,$A7,'Week 5 - Making'!$Y:$Y) -> 0
A8: Izabela Walicht | B8: =sumif('Week 1 - Making'!$A:$A,$A8,'Week 1 - Making'!$Y:$Y) -> 0 | C8: =sumif('Week 2 - Making'!$A:$A,$A8,'Week 2 - Making'!$Y:$Y) -> 0 | D8: =sumif('Week 3 - Making'!$A:$A,$A8,'Week 3 - Making'!$Y:$Y) -> 0 | E8: =sumif('Week 4 - Making'!$A:$A,$A8,'Week 4 - Making'!$Y:$Y) -> 0 | F8: =sumif('Week 5 - Making'!$A:$A,$A8,'Week 5 - Making'!$Y:$Y) -> 0
A9: Katie Hammond | B9: =sumif('Week 1 - Making'!$A:$A,$A9,'Week 1 - Making'!$Y:$Y) -> 0 | C9: =sumif('Week 2 - Making'!$A:$A,$A9,'Week 2 - Making'!$Y:$Y) -> 0 | D9: =sumif('Week 3 - Making'!$A:$A,$A9,'Week 3 - Making'!$Y:$Y) -> 0 | E9: =sumif('Week 4 - Making'!$A:$A,$A9,'Week 4 - Making'!$Y:$Y) -> 0 | F9: =sumif('Week 5 - Making'!$A:$A,$A9,'Week 5 - Making'!$Y:$Y) -> 0
A10: Lucie Sicova | B10: =sumif('Week 1 - Making'!$A:$A,$A10,'Week 1 - Making'!$Y:$Y) -> 0 | C10: =sumif('Week 2 - Making'!$A:$A,$A10,'Week 2 - Making'!$Y:$Y) -> 0 | D10: =sumif('Week 3 - Making'!$A:$A,$A10,'Week 3 - Making'!$Y:$Y) -> 0 | E10: =sumif('Week 4 - Making'!$A:$A,$A10,'Week 4 - Making'!$Y:$Y) -> 0 | F10: =sumif('Week 5 - Making'!$A:$A,$A10,'Week 5 - Making'!$Y:$Y) -> 0
A11: Lucie Vondrakova | B11: =sumif('Week 1 - Making'!$A:$A,$A11,'Week 1 - Making'!$Y:$Y) -> 0 | C11: =sumif('Week 2 - Making'!$A:$A,$A11,'Week 2 - Making'!$Y:$Y) -> 0 | D11: =sumif('Week 3 - Making'!$A:$A,$A11,'Week 3 - Making'!$Y:$Y) -> 0 | E11: =sumif('Week 4 - Making'!$A:$A,$A11,'Week 4 - Making'!$Y:$Y) -> 0 | F11: =sumif('Week 5 - Making'!$A:$A,$A11,'Week 5 - Making'!$Y:$Y) -> 0
A12: Lukasz Szybowski | B12: =sumif('Week 1 - Making'!$A:$A,$A12,'Week 1 - Making'!$Y:$Y) -> 0 | C12: =sumif('Week 2 - Making'!$A:$A,$A12,'Week 2 - Making'!$Y:$Y) -> 0 | D12: =sumif('Week 3 - Making'!$A:$A,$A12,'Week 3 - Making'!$Y:$Y) -> 0 | E12: =sumif('Week 4 - Making'!$A:$A,$A12,'Week 4 - Making'!$Y:$Y) -> 0 | F12: =sumif('Week 5 - Making'!$A:$A,$A12,'Week 5 - Making'!$Y:$Y) -> 0
